[<div class="wiki-body gollum-markdown-content instapaper_body" id="wiki-body">
        <div class="markdown-body">
          <p>Django Tastypie and Django version 1.7+ ship with support for geospatial queries.</p>
<p>I have sent pull requests that stop these being imported to tastypie if not installed at the system level. If however some other programme has installed them, you may see an error like the below.</p>
<p>In order to stop this error, run</p>
<pre><code>sudo apt-get remove libgdal1h
</code></pre>
<p>Or find the relevant repository for the .so.1 file which causes the error.</p>
<pre><code>[13/Jan/2016 06:07:42] "GET /dev/cbh_projects HTTP/1.1" 500 351442
Internal Server Error: /dev/cbh_projects
Traceback (most recent call last):
  File "/srv/chembiohub/anaconda2/envs/cbh/lib/python2.7/site-packages/django/core/handlers/base.py", line 87, in get_response
    response = middleware_method(request)
  File "/srv/chembiohub/anaconda2/envs/cbh/lib/python2.7/site-packages/django/middleware/common.py", line 72, in process_request
    if (not urlresolvers.is_valid_path(request.path_info, urlconf) and
  File "/srv/chembiohub/anaconda2/envs/cbh/lib/python2.7/site-packages/django/core/urlresolvers.py", line 619, in is_valid_path
    resolve(path, urlconf)
  File "/srv/chembiohub/anaconda2/envs/cbh/lib/python2.7/site-packages/django/core/urlresolvers.py", line 494, in resolve
    return get_resolver(urlconf).resolve(path)
  File "/srv/chembiohub/anaconda2/envs/cbh/lib/python2.7/site-packages/django/core/urlresolvers.py", line 343, in resolve
    for pattern in self.url_patterns:
  File "/srv/chembiohub/anaconda2/envs/cbh/lib/python2.7/site-packages/django/core/urlresolvers.py", line 372, in url_patterns
    patterns = getattr(self.urlconf_module, "urlpatterns", self.urlconf_module)
  File "/srv/chembiohub/anaconda2/envs/cbh/lib/python2.7/site-packages/django/core/urlresolvers.py", line 366, in urlconf_module
    self._urlconf_module = import_module(self.urlconf_name)
  File "/srv/chembiohub/anaconda2/envs/cbh/lib/python2.7/importlib/__init__.py", line 37, in import_module
    __import__(name)
  File "/srv/chembiohub/chembiohub_ws/deployment/urls.py", line 4, in &lt;module&gt;
    patt = ('',(r'^', include('cbh_chembl_ws_extension.urls')),
  File "/srv/chembiohub/anaconda2/envs/cbh/lib/python2.7/site-packages/django/conf/urls/__init__.py", line 28, in include
    urlconf_module = import_module(urlconf_module)
  File "/srv/chembiohub/anaconda2/envs/cbh/lib/python2.7/importlib/__init__.py", line 37, in import_module
    __import__(name)
  File "/srv/chembiohub/chembiohub_ws/cbh_chembl_ws_extension/urls.py", line 3, in &lt;module&gt;
    from cbh_core_ws.resources import Login, Logout
  File "/srv/chembiohub/chembiohub_ws/cbh_core_ws/resources.py", line 8, in &lt;module&gt;
    from tastypie.resources import ALL_WITH_RELATIONS
  File "/srv/chembiohub/anaconda2/envs/cbh/lib/python2.7/site-packages/tastypie/resources.py", line 19, in &lt;module&gt;
    from django.contrib.gis.db.models.fields import GeometryField
  File "/srv/chembiohub/anaconda2/envs/cbh/lib/python2.7/site-packages/django/contrib/gis/db/models/__init__.py", line 8, in &lt;module&gt;
    from django.contrib.gis.db.models.manager import GeoManager  # NOQA
  File "/srv/chembiohub/anaconda2/envs/cbh/lib/python2.7/site-packages/django/contrib/gis/db/models/manager.py", line 2, in &lt;module&gt;
    from django.contrib.gis.db.models.query import GeoQuerySet
  File "/srv/chembiohub/anaconda2/envs/cbh/lib/python2.7/site-packages/django/contrib/gis/db/models/query.py", line 6, in &lt;module&gt;
    from django.contrib.gis.db.models.fields import get_srid_info, PointField, LineStringField
  File "/srv/chembiohub/anaconda2/envs/cbh/lib/python2.7/site-packages/django/contrib/gis/db/models/fields.py", line 4, in &lt;module&gt;
    from django.contrib.gis import forms
  File "/srv/chembiohub/anaconda2/envs/cbh/lib/python2.7/site-packages/django/contrib/gis/forms/__init__.py", line 2, in &lt;module&gt;
    from .fields import (GeometryField, GeometryCollectionField, PointField,  # NOQA
  File "/srv/chembiohub/anaconda2/envs/cbh/lib/python2.7/site-packages/django/contrib/gis/forms/fields.py", line 8, in &lt;module&gt;
    from django.contrib.gis.geos import GEOSException, GEOSGeometry
  File "/srv/chembiohub/anaconda2/envs/cbh/lib/python2.7/site-packages/django/contrib/gis/geos/__init__.py", line 16, in &lt;module&gt;
    from .geometry import GEOSGeometry, wkt_regex, hex_regex
  File "/srv/chembiohub/anaconda2/envs/cbh/lib/python2.7/site-packages/django/contrib/gis/geos/geometry.py", line 14, in &lt;module&gt;
    from django.contrib.gis.gdal.error import SRSException
  File "/srv/chembiohub/anaconda2/envs/cbh/lib/python2.7/site-packages/django/contrib/gis/gdal/__init__.py", line 46, in &lt;module&gt;
    from django.contrib.gis.gdal.driver import Driver  # NOQA
  File "/srv/chembiohub/anaconda2/envs/cbh/lib/python2.7/site-packages/django/contrib/gis/gdal/driver.py", line 5, in &lt;module&gt;
    from django.contrib.gis.gdal.prototypes import ds as capi
  File "/srv/chembiohub/anaconda2/envs/cbh/lib/python2.7/site-packages/django/contrib/gis/gdal/prototypes/ds.py", line 8, in &lt;module&gt;
    from django.contrib.gis.gdal.libgdal import lgdal
  File "/srv/chembiohub/anaconda2/envs/cbh/lib/python2.7/site-packages/django/contrib/gis/gdal/libgdal.py", line 48, in &lt;module&gt;
    lgdal = CDLL(lib_path)
  File "/srv/chembiohub/anaconda2/envs/cbh/lib/python2.7/ctypes/__init__.py", line 365, in __init__
    self._handle = _dlopen(self._name, mode)
OSError: /usr/lib/libgdal.so.1: undefined symbol: sqlite3_column_table_name
</code></pre>

        </div>

    </div>]